<?xml version="1.0" encoding="utf-8"?>
<!-- =================================================================================== -->
<!-- |    This document was autogenerated by xacro from robots/dual_panda_robot.urdf.xacro | -->
<!-- |    EDITING THIS FILE BY HAND IS NOT RECOMMENDED                                 | -->
<!-- =================================================================================== -->
<robot name="dual_franka">
  <joint name="right_joint_fixed_base" type="fixed">
    <parent link="fixed_base"/>
    <child link="right_link0"/>
    <origin rpy="0 0 0" xyz="-0.02 -0.3 0.0"/>
  </joint>
  <link name="right_link0">
    <inertial>
      <mass value="2.90428"/>
      <origin rpy="0 0 0" xyz="-0.041271 -1.158905e-05 0.07"/>
      <inertia ixx="0.013404" ixy="0.0" ixz="0.0" iyy="0.017065" iyz="0.0" izz="0.020982"/>
    </inertial>
    <visual>
      <geometry>
        <mesh filename="package://franka_description/meshes/visual/link0.dae"/>
      </geometry>
    </visual>
    <collision>
      <origin rpy="0 1.57079632679 0" xyz="-0.075 0 0.06"/>
      <geometry>
        <cylinder length="0.03" radius="0.09"/>
      </geometry>
    </collision>
    <collision>
      <origin rpy="0 0 0" xyz="-0.06 0 0.06"/>
      <geometry>
        <sphere radius="0.09"/>
      </geometry>
    </collision>
    <collision>
      <origin rpy="0 0 0" xyz="-0.09 0 0.06"/>
      <geometry>
        <sphere radius="0.09"/>
      </geometry>
    </collision>
  </link>
  <link name="right_link1">
    <inertial>
      <mass value="2.43555"/>
      <origin rpy="0 0 0" xyz="-6.740570e-06 -0.037189 -0.068499"/>
      <inertia ixx="0.019285" ixy="0.0" ixz="0.0" iyy="0.014839" iyz="0.0" izz="0.009358"/>
    </inertial>
    <visual>
      <geometry>
        <mesh filename="package://franka_description/meshes/visual/link1.dae"/>
      </geometry>
    </visual>
    <collision>
      <origin rpy="0 0 0" xyz="0 0 -0.1915"/>
      <geometry>
        <cylinder length="0.2830" radius="0.09"/>
      </geometry>
    </collision>
    <collision>
      <origin rpy="0 0 0" xyz="0 0 -0.333"/>
      <geometry>
        <sphere radius="0.09"/>
      </geometry>
    </collision>
    <collision>
      <origin rpy="0 0 0" xyz="0 0 -0.05"/>
      <geometry>
        <sphere radius="0.09"/>
      </geometry>
    </collision>
  </link>
  <joint name="right_joint1" type="revolute">
    <safety_controller k_position="100.0" k_velocity="40.0" soft_lower_limit="-2.8973" soft_upper_limit="2.8973"/>
    <origin rpy="0 0 0" xyz="0 0 0.333"/>
    <parent link="right_link0"/>
    <child link="right_link1"/>
    <axis xyz="0 0 1"/>
    <limit effort="87" lower="-2.8973" upper="2.8973" velocity="2.1750"/>
  </joint>
  <link name="right_link2">
    <inertial>
      <mass value="2.45569"/>
      <origin rpy="0 0 0" xyz="-1.344109e-05 -0.069488 0.037195"/>
      <inertia ixx="0.019648" ixy="0.0" ixz="0.0" iyy="0.009436" iyz="0.0" izz="0.015168"/>
    </inertial>
    <visual>
      <geometry>
        <mesh filename="package://franka_description/meshes/visual/link2.dae"/>
      </geometry>
    </visual>
    <collision>
      <origin rpy="0 0 0" xyz="0 0 0"/>
      <geometry>
        <cylinder length="0.12" radius="0.09"/>
      </geometry>
    </collision>
    <collision>
      <origin rpy="0 0 0" xyz="0 0 -0.06"/>
      <geometry>
        <sphere radius="0.09"/>
      </geometry>
    </collision>
    <collision>
      <origin rpy="0 0 0" xyz="0 0 0.06"/>
      <geometry>
        <sphere radius="0.09"/>
      </geometry>
    </collision>
  </link>
  <joint name="right_joint2" type="revolute">
    <safety_controller k_position="100.0" k_velocity="40.0" soft_lower_limit="-1.7628" soft_upper_limit="1.7628"/>
    <origin rpy="-1.57079632679 0 0" xyz="0 0 0"/>
    <parent link="right_link1"/>
    <child link="right_link2"/>
    <axis xyz="0 0 1"/>
    <limit effort="87" lower="-1.7628" upper="1.7628" velocity="2.1750"/>
  </joint>
  <link name="right_link3">
    <inertial>
      <mass value="2.73471"/>
      <origin rpy="0 0 0" xyz="0.041242 0.028026 -0.032999"/>
      <inertia ixx="0.013344" ixy="0.0" ixz="0.0" iyy="0.015505" iyz="0.0" izz="0.01473"/>
    </inertial>
    <visual>
      <geometry>
        <mesh filename="package://franka_description/meshes/visual/link3.dae"/>
      </geometry>
    </visual>
    <collision>
      <origin rpy="0 0 0" xyz="0 0 -0.145"/>
      <geometry>
        <cylinder length="0.15" radius="0.09"/>
      </geometry>
    </collision>
    <collision>
      <origin rpy="0 0 0" xyz="0 0 -0.22"/>
      <geometry>
        <sphere radius="0.09"/>
      </geometry>
    </collision>
    <collision>
      <origin rpy="0 0 0" xyz="0 0 -0.07"/>
      <geometry>
        <sphere radius="0.09"/>
      </geometry>
    </collision>
  </link>
  <joint name="right_joint3" type="revolute">
    <safety_controller k_position="100.0" k_velocity="40.0" soft_lower_limit="-2.8973" soft_upper_limit="2.8973"/>
    <origin rpy="1.57079632679 0 0" xyz="0 -0.316 0"/>
    <parent link="right_link2"/>
    <child link="right_link3"/>
    <axis xyz="0 0 1"/>
    <limit effort="87" lower="-2.8973" upper="2.8973" velocity="2.1750"/>
  </joint>
  <link name="right_link4">
    <inertial>
      <mass value="2.78106"/>
      <origin rpy="0 0 0" xyz="-0.041256 0.0345 0.028032"/>
      <inertia ixx="0.013816" ixy="0.0" ixz="0.0" iyy="0.014979" iyz="0.0" izz="0.016014"/>
    </inertial>
    <visual>
      <geometry>
        <mesh filename="package://franka_description/meshes/visual/link4.dae"/>
      </geometry>
    </visual>
    <collision>
      <origin rpy="0 0 0" xyz="0 0 0"/>
      <geometry>
        <cylinder length="0.12" radius="0.09"/>
      </geometry>
    </collision>
    <collision>
      <origin rpy="0 0 0" xyz="0 0 0.06"/>
      <geometry>
        <sphere radius="0.09"/>
      </geometry>
    </collision>
    <collision>
      <origin rpy="0 0 0" xyz="0 0 -0.06"/>
      <geometry>
        <sphere radius="0.09"/>
      </geometry>
    </collision>
  </link>
  <joint name="right_joint4" type="revolute">
    <safety_controller k_position="100.0" k_velocity="40.0" soft_lower_limit="-3.0718" soft_upper_limit="-0.0698"/>
    <origin rpy="1.57079632679 0 0" xyz="0.0825 0 0"/>
    <parent link="right_link3"/>
    <child link="right_link4"/>
    <axis xyz="0 0 1"/>
    <limit effort="87" lower="-3.0718" upper="-0.0698" velocity="2.1750"/>
  </joint>
  <link name="right_link5">
    <inertial>
      <mass value="3.07672"/>
      <origin rpy="0 0 0" xyz="-8.943558e-06 0.03747 -0.103401"/>
      <inertia ixx="0.033599" ixy="0.0" ixz="0.0" iyy="0.027932" iyz="0.0" izz="0.011871"/>
    </inertial>
    <visual>
      <geometry>
        <mesh filename="package://franka_description/meshes/visual/link5.dae"/>
      </geometry>
    </visual>
    <collision>
      <origin rpy="0 0 0" xyz="0 0 -0.26"/>
      <geometry>
        <cylinder length="0.1" radius="0.09"/>
      </geometry>
    </collision>
    <collision>
      <origin rpy="0 0 0" xyz="0 0 -0.31"/>
      <geometry>
        <sphere radius="0.09"/>
      </geometry>
    </collision>
    <collision>
      <origin rpy="0 0 0" xyz="0 0 -0.21"/>
      <geometry>
        <sphere radius="0.09"/>
      </geometry>
    </collision>
    <collision>
      <origin rpy="0 0 0" xyz="0 0.08 -0.13"/>
      <geometry>
        <cylinder length="0.14" radius="0.055"/>
      </geometry>
    </collision>
    <collision>
      <origin rpy="0 0 0" xyz="0 0.08 -0.06"/>
      <geometry>
        <sphere radius="0.055"/>
      </geometry>
    </collision>
    <collision>
      <origin rpy="0 0 0" xyz="0 0.08 -0.20"/>
      <geometry>
        <sphere radius="0.055"/>
      </geometry>
    </collision>
  </link>
  <joint name="right_joint5" type="revolute">
    <safety_controller k_position="100.0" k_velocity="40.0" soft_lower_limit="-2.8973" soft_upper_limit="2.8973"/>
    <origin rpy="-1.57079632679 0 0" xyz="-0.0825 0.384 0"/>
    <parent link="right_link4"/>
    <child link="right_link5"/>
    <axis xyz="0 0 1"/>
    <limit effort="12" lower="-2.8973" upper="2.8973" velocity="2.6100"/>
  </joint>
  <link name="right_link6">
    <inertial>
      <mass value="1.16471"/>
      <origin rpy="0 0 0" xyz="0.042059 0.015232 0.006132"/>
      <inertia ixx="0.002689" ixy="0.0" ixz="0.0" iyy="0.004117" iyz="0.0" izz="0.004855"/>
    </inertial>
    <visual>
      <geometry>
        <mesh filename="package://franka_description/meshes/visual/link6.dae"/>
      </geometry>
    </visual>
    <collision>
      <origin rpy="0 0 0" xyz="0 0 -0.03"/>
      <geometry>
        <cylinder length="0.08" radius="0.08"/>
      </geometry>
    </collision>
    <collision>
      <origin rpy="0 0 0" xyz="0 0 0.01"/>
      <geometry>
        <sphere radius="0.08"/>
      </geometry>
    </collision>
    <collision>
      <origin rpy="0 0 0" xyz="0 0 -0.07"/>
      <geometry>
        <sphere radius="0.08"/>
      </geometry>
    </collision>
  </link>
  <joint name="right_joint6" type="revolute">
    <safety_controller k_position="100.0" k_velocity="40.0" soft_lower_limit="-0.0175" soft_upper_limit="3.7525"/>
    <origin rpy="1.57079632679 0 0" xyz="0 0 0"/>
    <parent link="right_link5"/>
    <child link="right_link6"/>
    <axis xyz="0 0 1"/>
    <limit effort="12" lower="-0.0175" upper="3.7525" velocity="2.6100"/>
  </joint>
  <link name="right_link7">
    <inertial>
      <mass value="0.418267"/>
      <origin rpy="0 0 0" xyz="0.01864 0.018625 0.0794"/>
      <inertia ixx="0.000652" ixy="0.0" ixz="0.0" iyy="0.000652" iyz="0.0" izz="0.001095"/>
    </inertial>
    <visual>
      <geometry>
        <mesh filename="package://franka_description/meshes/visual/link7.dae"/>
      </geometry>
    </visual>
    <collision>
      <origin rpy="0 0 0" xyz="0 0 0.01"/>
      <geometry>
        <cylinder length="0.14" radius="0.07"/>
      </geometry>
    </collision>
    <collision>
      <origin rpy="0 0 0" xyz="0 0 0.08"/>
      <geometry>
        <sphere radius="0.07"/>
      </geometry>
    </collision>
    <collision>
      <origin rpy="0 0 0" xyz="0 0 -0.06"/>
      <geometry>
        <sphere radius="0.07"/>
      </geometry>
    </collision>
  </link>
  <joint name="right_joint7" type="revolute">
    <safety_controller k_position="100.0" k_velocity="40.0" soft_lower_limit="-2.8973" soft_upper_limit="2.8973"/>
    <origin rpy="1.57079632679 0 0" xyz="0.088 0 0"/>
    <parent link="right_link6"/>
    <child link="right_link7"/>
    <axis xyz="0 0 1"/>
    <limit effort="12" lower="-2.8973" upper="2.8973" velocity="2.6100"/>
  </joint>
  <link name="right_link8">
    <inertial>
      <mass value="0.01"/>
      <origin rpy="0 0 0" xyz="0.0 0.0 0.0"/>
      <inertia ixx="0.000001" ixy="0.0" ixz="0.0" iyy="0.000001" iyz="0.0" izz="0.000001"/>
    </inertial>
    <collision>
      <origin rpy="3.14159265359 1.57079632679 1.57079632679" xyz="0.0424 0.0424 -0.0250"/>
      <geometry>
        <cylinder length="0.01" radius="0.06"/>
      </geometry>
    </collision>
    <collision>
      <origin rpy="0 0 0" xyz="0.0424 0.0424 -0.02"/>
      <geometry>
        <sphere radius="0.06"/>
      </geometry>
    </collision>
    <collision>
      <origin rpy="0 0 0" xyz="0.0424 0.0424 -0.03"/>
      <geometry>
        <sphere radius="0.06"/>
      </geometry>
    </collision>
  </link>
  <joint name="right_joint8" type="fixed">
    <origin rpy="0 0 0" xyz="0 0 0.107"/>
    <parent link="right_link7"/>
    <child link="right_link8"/>
  </joint>
  <joint name="right_hand_joint" type="fixed">
    <parent link="right_link8"/>
    <child link="right_hand"/>
    <origin rpy="0 0 -0.785398163397" xyz="0 0 0"/>
  </joint>
  <link name="right_hand">
    <inertial>
      <mass value="0.01"/>
      <origin rpy="0 0 0" xyz="0.0 0.0 0.0"/>
      <inertia ixx="0.000001" ixy="0.0" ixz="0.0" iyy="0.000001" iyz="0.0" izz="0.000001"/>
    </inertial>
    <visual>
      <geometry>
        <mesh filename="package://franka_description/meshes/visual/hand.dae"/>
      </geometry>
    </visual>
    <collision>
      <origin xyz="0.0 0.0 0.0285"/>
      <geometry>
        <box size="0.056 0.2 0.074"/>
      </geometry>
    </collision>
    <!--
      <collision>
        <origin xyz="0 0 0.04" rpy="0 ${pi/2} ${pi/2}"/>
        <geometry>
          <cylinder radius="${0.04+safety_distance}" length="0.1" />
        </geometry>
      </collision>
      <collision>
        <origin xyz="0 -0.05 0.04" rpy="0 0 0"/>
        <geometry>
          <sphere radius="${0.04+safety_distance}"  />
        </geometry>
      </collision>
      <collision>
        <origin xyz="0 0.05 0.04" rpy="0 0 0"/>
        <geometry>
          <sphere radius="${0.04+safety_distance}"  />
        </geometry>
      </collision>
      <collision>
        <origin xyz="0 0 0.1" rpy="0 ${pi/2} ${pi/2}"/>
        <geometry>
          <cylinder radius="${0.02+safety_distance}" length="0.1" />
        </geometry>
      </collision>
      <collision>
        <origin xyz="0 -0.05 0.1" rpy="0 0 0"/>
        <geometry>
          <sphere radius="${0.02+safety_distance}"  />
        </geometry>
      </collision>
      <collision>
        <origin xyz="0 0.05 0.1" rpy="0 0 0"/>
        <geometry>
          <sphere radius="${0.02+safety_distance}"  />
        </geometry>
      </collision>
      -->
  </link>
  <link name="right_leftfinger">
    <inertial>
      <mass value="0.014505"/>
      <origin rpy="0 0 0" xyz="3.299713e-07 0.013131 0.027017"/>
      <inertia ixx="4.338623e-06" ixy="0.0" ixz="0.0" iyy="4.027488e-06" iyz="0.0" izz="1.377502e-06"/>
    </inertial>
    <visual>
      <geometry>
        <mesh filename="package://franka_description/meshes/visual/finger.dae"/>
      </geometry>
    </visual>
    <collision>
      <origin xyz="0.0 0.0131 0.027"/>
      <geometry>
        <box size="0.021 0.02643 0.0538"/>
      </geometry>
    </collision>
  </link>
  <link name="right_rightfinger">
    <inertial>
      <mass value="0.014505"/>
      <origin rpy="0 0 0" xyz="3.299713e-07 0.013131 0.027017"/>
      <inertia ixx="4.338623e-06" ixy="0.0" ixz="0.0" iyy="4.027488e-06" iyz="0.0" izz="1.377502e-06"/>
    </inertial>
    <visual>
      <origin rpy="0 0 3.14159265359" xyz="0 0 0"/>
      <geometry>
        <mesh filename="package://franka_description/meshes/visual/finger.dae"/>
      </geometry>
    </visual>
    <collision>
      <origin rpy="0 0 3.14159265359" xyz="0.0 -0.0131 0.027"/>
      <geometry>
        <box size="0.021 0.02643 0.0538"/>
      </geometry>
    </collision>
  </link>
  <joint name="right_finger_joint1" type="prismatic">
    <parent link="right_hand"/>
    <child link="right_leftfinger"/>
    <origin rpy="0 0 0" xyz="0 0 0.0584"/>
    <axis xyz="0 1 0"/>
    <limit effort="20" lower="0.0" upper="0.04" velocity="0.2"/>
  </joint>
  <joint name="right_finger_joint2" type="prismatic">
    <parent link="right_hand"/>
    <child link="right_rightfinger"/>
    <origin rpy="0 0 0" xyz="0 0 0.0584"/>
    <axis xyz="0 -1 0"/>
    <limit effort="20" lower="0.0" upper="0.04" velocity="0.2"/>
    <mimic joint="right_finger_joint1"/>
  </joint>
  <joint name="left_joint_fixed_base" type="fixed">
    <parent link="fixed_base"/>
    <child link="left_link0"/>
    <origin rpy="0 0 0" xyz="-0.02  0.3 0.0"/>
  </joint>
  <link name="left_link0">
    <inertial>
      <mass value="2.90428"/>
      <origin rpy="0 0 0" xyz="-0.041271 -1.158905e-05 0.07"/>
      <inertia ixx="0.013404" ixy="0.0" ixz="0.0" iyy="0.017065" iyz="0.0" izz="0.020982"/>
    </inertial>
    <visual>
      <geometry>
        <mesh filename="package://franka_description/meshes/visual/link0.dae"/>
      </geometry>
    </visual>
    <collision>
      <origin rpy="0 1.57079632679 0" xyz="-0.075 0 0.06"/>
      <geometry>
        <cylinder length="0.03" radius="0.09"/>
      </geometry>
    </collision>
    <collision>
      <origin rpy="0 0 0" xyz="-0.06 0 0.06"/>
      <geometry>
        <sphere radius="0.09"/>
      </geometry>
    </collision>
    <collision>
      <origin rpy="0 0 0" xyz="-0.09 0 0.06"/>
      <geometry>
        <sphere radius="0.09"/>
      </geometry>
    </collision>
  </link>
  <link name="left_link1">
    <inertial>
      <mass value="2.43555"/>
      <origin rpy="0 0 0" xyz="-6.740570e-06 -0.037189 -0.068499"/>
      <inertia ixx="0.019285" ixy="0.0" ixz="0.0" iyy="0.014839" iyz="0.0" izz="0.009358"/>
    </inertial>
    <visual>
      <geometry>
        <mesh filename="package://franka_description/meshes/visual/link1.dae"/>
      </geometry>
    </visual>
    <collision>
      <origin rpy="0 0 0" xyz="0 0 -0.1915"/>
      <geometry>
        <cylinder length="0.2830" radius="0.09"/>
      </geometry>
    </collision>
    <collision>
      <origin rpy="0 0 0" xyz="0 0 -0.333"/>
      <geometry>
        <sphere radius="0.09"/>
      </geometry>
    </collision>
    <collision>
      <origin rpy="0 0 0" xyz="0 0 -0.05"/>
      <geometry>
        <sphere radius="0.09"/>
      </geometry>
    </collision>
  </link>
  <joint name="left_joint1" type="revolute">
    <safety_controller k_position="100.0" k_velocity="40.0" soft_lower_limit="-2.8973" soft_upper_limit="2.8973"/>
    <origin rpy="0 0 0" xyz="0 0 0.333"/>
    <parent link="left_link0"/>
    <child link="left_link1"/>
    <axis xyz="0 0 1"/>
    <limit effort="87" lower="-2.8973" upper="2.8973" velocity="2.1750"/>
  </joint>
  <link name="left_link2">
    <inertial>
      <mass value="2.45569"/>
      <origin rpy="0 0 0" xyz="-1.344109e-05 -0.069488 0.037195"/>
      <inertia ixx="0.019648" ixy="0.0" ixz="0.0" iyy="0.009436" iyz="0.0" izz="0.015168"/>
    </inertial>
    <visual>
      <geometry>
        <mesh filename="package://franka_description/meshes/visual/link2.dae"/>
      </geometry>
    </visual>
    <collision>
      <origin rpy="0 0 0" xyz="0 0 0"/>
      <geometry>
        <cylinder length="0.12" radius="0.09"/>
      </geometry>
    </collision>
    <collision>
      <origin rpy="0 0 0" xyz="0 0 -0.06"/>
      <geometry>
        <sphere radius="0.09"/>
      </geometry>
    </collision>
    <collision>
      <origin rpy="0 0 0" xyz="0 0 0.06"/>
      <geometry>
        <sphere radius="0.09"/>
      </geometry>
    </collision>
  </link>
  <joint name="left_joint2" type="revolute">
    <safety_controller k_position="100.0" k_velocity="40.0" soft_lower_limit="-1.7628" soft_upper_limit="1.7628"/>
    <origin rpy="-1.57079632679 0 0" xyz="0 0 0"/>
    <parent link="left_link1"/>
    <child link="left_link2"/>
    <axis xyz="0 0 1"/>
    <limit effort="87" lower="-1.7628" upper="1.7628" velocity="2.1750"/>
  </joint>
  <link name="left_link3">
    <inertial>
      <mass value="2.73471"/>
      <origin rpy="0 0 0" xyz="0.041242 0.028026 -0.032999"/>
      <inertia ixx="0.013344" ixy="0.0" ixz="0.0" iyy="0.015505" iyz="0.0" izz="0.01473"/>
    </inertial>
    <visual>
      <geometry>
        <mesh filename="package://franka_description/meshes/visual/link3.dae"/>
      </geometry>
    </visual>
    <collision>
      <origin rpy="0 0 0" xyz="0 0 -0.145"/>
      <geometry>
        <cylinder length="0.15" radius="0.09"/>
      </geometry>
    </collision>
    <collision>
      <origin rpy="0 0 0" xyz="0 0 -0.22"/>
      <geometry>
        <sphere radius="0.09"/>
      </geometry>
    </collision>
    <collision>
      <origin rpy="0 0 0" xyz="0 0 -0.07"/>
      <geometry>
        <sphere radius="0.09"/>
      </geometry>
    </collision>
  </link>
  <joint name="left_joint3" type="revolute">
    <safety_controller k_position="100.0" k_velocity="40.0" soft_lower_limit="-2.8973" soft_upper_limit="2.8973"/>
    <origin rpy="1.57079632679 0 0" xyz="0 -0.316 0"/>
    <parent link="left_link2"/>
    <child link="left_link3"/>
    <axis xyz="0 0 1"/>
    <limit effort="87" lower="-2.8973" upper="2.8973" velocity="2.1750"/>
  </joint>
  <link name="left_link4">
    <inertial>
      <mass value="2.78106"/>
      <origin rpy="0 0 0" xyz="-0.041256 0.0345 0.028032"/>
      <inertia ixx="0.013816" ixy="0.0" ixz="0.0" iyy="0.014979" iyz="0.0" izz="0.016014"/>
    </inertial>
    <visual>
      <geometry>
        <mesh filename="package://franka_description/meshes/visual/link4.dae"/>
      </geometry>
    </visual>
    <collision>
      <origin rpy="0 0 0" xyz="0 0 0"/>
      <geometry>
        <cylinder length="0.12" radius="0.09"/>
      </geometry>
    </collision>
    <collision>
      <origin rpy="0 0 0" xyz="0 0 0.06"/>
      <geometry>
        <sphere radius="0.09"/>
      </geometry>
    </collision>
    <collision>
      <origin rpy="0 0 0" xyz="0 0 -0.06"/>
      <geometry>
        <sphere radius="0.09"/>
      </geometry>
    </collision>
  </link>
  <joint name="left_joint4" type="revolute">
    <safety_controller k_position="100.0" k_velocity="40.0" soft_lower_limit="-3.0718" soft_upper_limit="-0.0698"/>
    <origin rpy="1.57079632679 0 0" xyz="0.0825 0 0"/>
    <parent link="left_link3"/>
    <child link="left_link4"/>
    <axis xyz="0 0 1"/>
    <limit effort="87" lower="-3.0718" upper="-0.0698" velocity="2.1750"/>
  </joint>
  <link name="left_link5">
    <inertial>
      <mass value="3.07672"/>
      <origin rpy="0 0 0" xyz="-8.943558e-06 0.03747 -0.103401"/>
      <inertia ixx="0.033599" ixy="0.0" ixz="0.0" iyy="0.027932" iyz="0.0" izz="0.011871"/>
    </inertial>
    <visual>
      <geometry>
        <mesh filename="package://franka_description/meshes/visual/link5.dae"/>
      </geometry>
    </visual>
    <collision>
      <origin rpy="0 0 0" xyz="0 0 -0.26"/>
      <geometry>
        <cylinder length="0.1" radius="0.09"/>
      </geometry>
    </collision>
    <collision>
      <origin rpy="0 0 0" xyz="0 0 -0.31"/>
      <geometry>
        <sphere radius="0.09"/>
      </geometry>
    </collision>
    <collision>
      <origin rpy="0 0 0" xyz="0 0 -0.21"/>
      <geometry>
        <sphere radius="0.09"/>
      </geometry>
    </collision>
    <collision>
      <origin rpy="0 0 0" xyz="0 0.08 -0.13"/>
      <geometry>
        <cylinder length="0.14" radius="0.055"/>
      </geometry>
    </collision>
    <collision>
      <origin rpy="0 0 0" xyz="0 0.08 -0.06"/>
      <geometry>
        <sphere radius="0.055"/>
      </geometry>
    </collision>
    <collision>
      <origin rpy="0 0 0" xyz="0 0.08 -0.20"/>
      <geometry>
        <sphere radius="0.055"/>
      </geometry>
    </collision>
  </link>
  <joint name="left_joint5" type="revolute">
    <safety_controller k_position="100.0" k_velocity="40.0" soft_lower_limit="-2.8973" soft_upper_limit="2.8973"/>
    <origin rpy="-1.57079632679 0 0" xyz="-0.0825 0.384 0"/>
    <parent link="left_link4"/>
    <child link="left_link5"/>
    <axis xyz="0 0 1"/>
    <limit effort="12" lower="-2.8973" upper="2.8973" velocity="2.6100"/>
  </joint>
  <link name="left_link6">
    <inertial>
      <mass value="1.16471"/>
      <origin rpy="0 0 0" xyz="0.042059 0.015232 0.006132"/>
      <inertia ixx="0.002689" ixy="0.0" ixz="0.0" iyy="0.004117" iyz="0.0" izz="0.004855"/>
    </inertial>
    <visual>
      <geometry>
        <mesh filename="package://franka_description/meshes/visual/link6.dae"/>
      </geometry>
    </visual>
    <collision>
      <origin rpy="0 0 0" xyz="0 0 -0.03"/>
      <geometry>
        <cylinder length="0.08" radius="0.08"/>
      </geometry>
    </collision>
    <collision>
      <origin rpy="0 0 0" xyz="0 0 0.01"/>
      <geometry>
        <sphere radius="0.08"/>
      </geometry>
    </collision>
    <collision>
      <origin rpy="0 0 0" xyz="0 0 -0.07"/>
      <geometry>
        <sphere radius="0.08"/>
      </geometry>
    </collision>
  </link>
  <joint name="left_joint6" type="revolute">
    <safety_controller k_position="100.0" k_velocity="40.0" soft_lower_limit="-0.0175" soft_upper_limit="3.7525"/>
    <origin rpy="1.57079632679 0 0" xyz="0 0 0"/>
    <parent link="left_link5"/>
    <child link="left_link6"/>
    <axis xyz="0 0 1"/>
    <limit effort="12" lower="-0.0175" upper="3.7525" velocity="2.6100"/>
  </joint>
  <link name="left_link7">
    <inertial>
      <mass value="0.418267"/>
      <origin rpy="0 0 0" xyz="0.01864 0.018625 0.0794"/>
      <inertia ixx="0.000652" ixy="0.0" ixz="0.0" iyy="0.000652" iyz="0.0" izz="0.001095"/>
    </inertial>
    <visual>
      <geometry>
        <mesh filename="package://franka_description/meshes/visual/link7.dae"/>
      </geometry>
    </visual>
    <collision>
      <origin rpy="0 0 0" xyz="0 0 0.01"/>
      <geometry>
        <cylinder length="0.14" radius="0.07"/>
      </geometry>
    </collision>
    <collision>
      <origin rpy="0 0 0" xyz="0 0 0.08"/>
      <geometry>
        <sphere radius="0.07"/>
      </geometry>
    </collision>
    <collision>
      <origin rpy="0 0 0" xyz="0 0 -0.06"/>
      <geometry>
        <sphere radius="0.07"/>
      </geometry>
    </collision>
  </link>
  <joint name="left_joint7" type="revolute">
    <safety_controller k_position="100.0" k_velocity="40.0" soft_lower_limit="-2.8973" soft_upper_limit="2.8973"/>
    <origin rpy="1.57079632679 0 0" xyz="0.088 0 0"/>
    <parent link="left_link6"/>
    <child link="left_link7"/>
    <axis xyz="0 0 1"/>
    <limit effort="12" lower="-2.8973" upper="2.8973" velocity="2.6100"/>
  </joint>
  <link name="left_link8">
    <inertial>
      <mass value="0.01"/>
      <origin rpy="0 0 0" xyz="0.0 0.0 0.0"/>
      <inertia ixx="0.000001" ixy="0.0" ixz="0.0" iyy="0.000001" iyz="0.0" izz="0.000001"/>
    </inertial>
    <collision>
      <origin rpy="3.14159265359 1.57079632679 1.57079632679" xyz="0.0424 0.0424 -0.0250"/>
      <geometry>
        <cylinder length="0.01" radius="0.06"/>
      </geometry>
    </collision>
    <collision>
      <origin rpy="0 0 0" xyz="0.0424 0.0424 -0.02"/>
      <geometry>
        <sphere radius="0.06"/>
      </geometry>
    </collision>
    <collision>
      <origin rpy="0 0 0" xyz="0.0424 0.0424 -0.03"/>
      <geometry>
        <sphere radius="0.06"/>
      </geometry>
    </collision>
  </link>
  <joint name="left_joint8" type="fixed">
    <origin rpy="0 0 0" xyz="0 0 0.107"/>
    <parent link="left_link7"/>
    <child link="left_link8"/>
  </joint>
  <joint name="left_hand_joint" type="fixed">
    <parent link="left_link8"/>
    <child link="left_hand"/>
    <origin rpy="0 0 -0.785398163397" xyz="0 0 0"/>
  </joint>
  <link name="left_hand">
    <inertial>
      <mass value="0.01"/>
      <origin rpy="0 0 0" xyz="0.0 0.0 0.0"/>
      <inertia ixx="0.000001" ixy="0.0" ixz="0.0" iyy="0.000001" iyz="0.0" izz="0.000001"/>
    </inertial>
    <visual>
      <geometry>
        <mesh filename="package://franka_description/meshes/visual/hand.dae"/>
      </geometry>
    </visual>
    <collision>
      <origin xyz="0.0 0.0 0.0285"/>
      <geometry>
        <box size="0.056 0.2 0.074"/>
      </geometry>
    </collision>
    <!--
      <collision>
        <origin xyz="0 0 0.04" rpy="0 ${pi/2} ${pi/2}"/>
        <geometry>
          <cylinder radius="${0.04+safety_distance}" length="0.1" />
        </geometry>
      </collision>
      <collision>
        <origin xyz="0 -0.05 0.04" rpy="0 0 0"/>
        <geometry>
          <sphere radius="${0.04+safety_distance}"  />
        </geometry>
      </collision>
      <collision>
        <origin xyz="0 0.05 0.04" rpy="0 0 0"/>
        <geometry>
          <sphere radius="${0.04+safety_distance}"  />
        </geometry>
      </collision>
      <collision>
        <origin xyz="0 0 0.1" rpy="0 ${pi/2} ${pi/2}"/>
        <geometry>
          <cylinder radius="${0.02+safety_distance}" length="0.1" />
        </geometry>
      </collision>
      <collision>
        <origin xyz="0 -0.05 0.1" rpy="0 0 0"/>
        <geometry>
          <sphere radius="${0.02+safety_distance}"  />
        </geometry>
      </collision>
      <collision>
        <origin xyz="0 0.05 0.1" rpy="0 0 0"/>
        <geometry>
          <sphere radius="${0.02+safety_distance}"  />
        </geometry>
      </collision>
      -->
  </link>
  <link name="left_leftfinger">
    <inertial>
      <mass value="0.014505"/>
      <origin rpy="0 0 0" xyz="3.299713e-07 0.013131 0.027017"/>
      <inertia ixx="4.338623e-06" ixy="0.0" ixz="0.0" iyy="4.027488e-06" iyz="0.0" izz="1.377502e-06"/>
    </inertial>
    <visual>
      <geometry>
        <mesh filename="package://franka_description/meshes/visual/finger.dae"/>
      </geometry>
    </visual>
    <collision>
      <origin xyz="0.0 0.0131 0.027"/>
      <geometry>
        <box size="0.021 0.02643 0.0538"/>
      </geometry>
    </collision>
  </link>
  <link name="left_rightfinger">
    <inertial>
      <mass value="0.014505"/>
      <origin rpy="0 0 0" xyz="3.299713e-07 0.013131 0.027017"/>
      <inertia ixx="4.338623e-06" ixy="0.0" ixz="0.0" iyy="4.027488e-06" iyz="0.0" izz="1.377502e-06"/>
    </inertial>
    <visual>
      <origin rpy="0 0 3.14159265359" xyz="0 0 0"/>
      <geometry>
        <mesh filename="package://franka_description/meshes/visual/finger.dae"/>
      </geometry>
    </visual>
    <collision>
      <origin rpy="0 0 3.14159265359" xyz="0.0 -0.0131 0.027"/>
      <geometry>
        <box size="0.021 0.02643 0.0538"/>
      </geometry>
    </collision>
  </link>
  <joint name="left_finger_joint1" type="prismatic">
    <parent link="left_hand"/>
    <child link="left_leftfinger"/>
    <origin rpy="0 0 0" xyz="0 0 0.0584"/>
    <axis xyz="0 1 0"/>
    <limit effort="20" lower="0.0" upper="0.04" velocity="0.2"/>
  </joint>
  <joint name="left_finger_joint2" type="prismatic">
    <parent link="left_hand"/>
    <child link="left_rightfinger"/>
    <origin rpy="0 0 0" xyz="0 0 0.0584"/>
    <axis xyz="0 -1 0"/>
    <limit effort="20" lower="0.0" upper="0.04" velocity="0.2"/>
    <mimic joint="left_finger_joint1"/>
  </joint>
  <link name="fixed_base"/>
  <link name="dual_arm_base">
    <visual>
      <origin rpy="1.5707963267949 0.0 0.0" xyz="0 -0.4 0"/>
      <geometry>
        <mesh filename="package://franka_description/meshes/dual_franka_base.dae" scale="0.001 0.001 0.001"/>
      </geometry>
      <material name="misumi">
        <color rgba="0.75 0.75 0.75 1.0"/>
      </material>
    </visual>
    <collision>
      <origin rpy="1.5707963267949 0.0 0.0" xyz="0 -0.4 0"/>
      <geometry>
        <mesh filename="package://franka_description/meshes/dual_franka_base.dae" scale="0.001 0.001 0.001"/>
      </geometry>
    </collision>
    <inertial>
      <mass value="1000"/>
      <origin rpy="0 0 0" xyz="0.0 0.0 0.2"/>
      <inertia ixx="10.0" ixy="0.0" ixz="0.0" iyy="10.0" iyz="0.0" izz="10.0"/>
    </inertial>
  </link>
  <joint name="base_to_fixed" type="fixed">
    <parent link="dual_arm_base"/>
    <child link="fixed_base"/>
    <origin rpy="0.0 0.0 0.0" xyz="-0.08 0.0 0.8"/>
  </joint>
  <!--link name="table_plane">
    <visual>
      <origin xyz="0.3 0 0.01" />
      <geometry>
        <box size="0.6 1.2 0.02" />
      </geometry>
      <material name="table">
        <color rgba="0.7 0.6 0.5 1.0"/>
      </material>
    </visual>
    <collision>
      <origin xyz="0.3 0 0.01" />
      <geometry>
        <box size="0.6 1.2 0.02" />
      </geometry>
    </collision>
  </link-->
  <link name="controller_plane0">
    <visual>
      <origin xyz="0.3 0 0.01"/>
      <geometry>
        <box size="0.6 0.8 0.02"/>
      </geometry>
      <material name="plane">
        <color rgba="0.6 0.6 0.6 1.0"/>
      </material>
    </visual>
  </link>
  <link name="controller_plane1">
    <visual>
      <origin xyz="0.3 0 0.01"/>
      <geometry>
        <box size="0.6 0.8 0.02"/>
      </geometry>
      <material name="plane"/>
    </visual>
  </link>
  <!--joint name="base_to_table_plane" type="fixed">
    <parent link="dual_arm_base" />
    <child  link="table_plane" />
    <origin xyz="0.0 0.0 0.8" rpy="0.0 0.0 0.0" />
  </joint-->
  <joint name="base_to_c_plane0" type="fixed">
    <parent link="dual_arm_base"/>
    <child link="controller_plane0"/>
    <origin rpy="0.0 0.0 0.0" xyz="0.0 0.0 0.2"/>
  </joint>
  <joint name="base_to_c_plane1" type="fixed">
    <parent link="dual_arm_base"/>
    <child link="controller_plane1"/>
    <origin rpy="0.0 0.0 0.0" xyz="0.0 0.0 0.5"/>
  </joint>
  <link name="controller0">
    <visual>
      <origin xyz="0.3 0 0.134"/>
      <geometry>
        <box size="0.475 0.423 0.268"/>
      </geometry>
      <material name="controller">
        <color rgba="0.5 0.5 0.6 1.0"/>
      </material>
    </visual>
  </link>
  <link name="controller1">
    <visual>
      <origin xyz="0.3 0 0.134"/>
      <geometry>
        <box size="0.475 0.423 0.268"/>
      </geometry>
      <material name="controller"/>
    </visual>
  </link>
  <joint name="base_to_c0" type="fixed">
    <parent link="dual_arm_base"/>
    <child link="controller0"/>
    <origin rpy="0.0 0.0 0.0" xyz="0.0 0.0 0.22"/>
  </joint>
  <joint name="base_to_c1" type="fixed">
    <parent link="dual_arm_base"/>
    <child link="controller1"/>
    <origin rpy="0.0 0.0 0.0" xyz="0.0 0.0 0.52"/>
  </joint>
  <!--link name="dual_arm_booth">
    <visual>
      <origin rpy="1.5707963267949 0.0 0.0" xyz="0 -0.75 0"/>
      <geometry>
        <mesh filename="package://franka_description/meshes/dual_franka_booth.stl"
              scale="0.001 0.001 0.001" />
      </geometry>
      <material name="misumi">
        <color rgba="0.75 0.75 0.75 1.0"/>
      </material>
    </visual>
    <collision>
      <origin rpy="1.5707963267949 0.0 0.0" xyz="0 -0.75 0"/>
      <geometry>
        <mesh filename="package://franka_description/meshes/dual_franka_booth.stl"
              scale="0.001 0.001 0.001" />
      </geometry>
    </collision>
    <inertial>
      <mass value="1000"/>
      <origin rpy="0 0 0" xyz="0.0 0.0 0.8"/>
      <inertia ixx="1.0" ixy="0.0" ixz="0.0" iyy="1.0" iyz="0.0" izz="1.0"/>
    </inertial>
  </link>
  <joint name="base_to_booth" type="fixed">
    <parent link="dual_arm_base"/>
    <child link="dual_arm_booth"/>
    <origin rpy="0.0 0.0 0.0" xyz="-0.11 0.0 0.0"/>
  </joint-->
  <link name="display">
    <visual>
      <geometry>
        <!--box size="0.03 0.817 0.342"/-->
        <!-- 34inch wide -->
        <box size="0.015 0.165 0.150"/>
        <!-- 12inch -->
      </geometry>
      <material name="Display">
        <color rgba="0.15 0.15 0.15 1.0"/>
      </material>
    </visual>
    <collision>
      <geometry>
        <!--box size="0.03 0.817 0.342"/-->
        <box size="0.015 0.165 0.150"/>
        <!-- 12inch -->
      </geometry>
    </collision>
  </link>
  <joint name="base_to_dispaly" type="fixed">
    <parent link="dual_arm_base"/>
    <child link="display"/>
    <origin rpy="0.0 0.2 0.0" xyz="0.0 0.0 1.66"/>
  </joint>
  <!--xacro:include filename="$(find openni_description)/model/kinect.urdf.xacro" /-->
  <gazebo reference="pan_tilt_BASE">
    <mu1>0.9</mu1>
    <mu2>0.9</mu2>
  </gazebo>
  <link name="pan_tilt_BASE">
    <inertial>
      <mass value="0.112"/>
      <origin rpy="0 0 0" xyz="-2.187035e-19 -0.012536 -0.000367"/>
      <inertia ixx="3.737235e-05" ixy="-1.093518e-22" ixz="-1.117885e-21" iyy="2.575474e-05" iyz="-9.334821e-07" izz="2.726761e-05"/>
    </inertial>
    <visual>
      <origin rpy="0.00000000 -0.00000000 0.00000000" xyz="0.000000 0.000000 0.000000"/>
      <geometry>
        <mesh filename="package://ur_e_description/pan_tilt/meshes/xm430_dynamixel.dae" scale="1.000000 1.000000 1.000000"/>
      </geometry>
    </visual>
    <collision>
      <origin rpy="0.00000000 -0.00000000 0.00000000" xyz="0.000000 0.000000 0.000000"/>
      <geometry>
        <mesh filename="package://ur_e_description/pan_tilt/meshes/xm430_dynamixel.dae" scale="1.000000 1.000000 1.000000"/>
      </geometry>
    </collision>
    <visual>
      <origin rpy="-1.57079633 0.00000000 3.14159265" xyz="-0.000000 -0.000000 -0.003000"/>
      <geometry>
        <mesh filename="package://ur_e_description/pan_tilt/meshes/fr12_x102.dae" scale="1.000000 1.000000 1.000000"/>
      </geometry>
    </visual>
    <collision>
      <origin rpy="-1.57079633 0.00000000 3.14159265" xyz="-0.000000 -0.000000 -0.003000"/>
      <geometry>
        <mesh filename="package://ur_e_description/pan_tilt/meshes/fr12_x102.dae" scale="1.000000 1.000000 1.000000"/>
      </geometry>
    </collision>
  </link>
  <gazebo reference="pan_tilt_LINK0">
    <mu1>0.9</mu1>
    <mu2>0.9</mu2>
  </gazebo>
  <link name="pan_tilt_LINK0">
    <inertial>
      <mass value="0.015"/>
      <origin rpy="0 0 0" xyz="0.0 0.01345 -0.019"/>
      <inertia ixx="1.969763e-06" ixy="0.0" ixz="0.0" iyy="3.012500e-06" iyz="9.466331e-38" izz="3.159763e-06"/>
    </inertial>
    <visual>
      <origin rpy="0.00000000 1.57079633 0.00000000" xyz="0.000000 0.000000 -0.019000"/>
      <geometry>
        <mesh filename="package://ur_e_description/pan_tilt/meshes/fr12_h101s.dae" scale="1.000000 1.000000 1.000000"/>
      </geometry>
    </visual>
    <collision>
      <origin rpy="0.00000000 1.57079633 0.00000000" xyz="0.000000 0.000000 -0.019000"/>
      <geometry>
        <mesh filename="package://ur_e_description/pan_tilt/meshes/fr12_h101s.dae" scale="1.000000 1.000000 1.000000"/>
      </geometry>
    </collision>
  </link>
  <transmission name="pan_tilt_JOINT0_trans">
    <type>transmission_interface/SimpleTransmission</type>
    <joint name="pan_tilt_JOINT0">
      <hardwareInterface>hardware_interface/VelocityJointInterface</hardwareInterface>
      <!--hardwareInterface>hardware_interface/EffortJointInterface</hardwareInterface-->
    </joint>
    <actuator name="pan_tilt_JOINT0_motor">
      <hardwareInterface>hardware_interface/VelocityJointInterface</hardwareInterface>
      <!--hardwareInterface>hardware_interface/EffortJointInterface</hardwareInterface-->
      <mechanicalReduction>1</mechanicalReduction>
    </actuator>
  </transmission>
  <joint name="pan_tilt_JOINT0" type="revolute">
    <parent link="pan_tilt_BASE"/>
    <child link="pan_tilt_LINK0"/>
    <origin rpy="0.00000000 -0.00000000 0.00000000" xyz="0.000000 0.000000 0.019000"/>
    <axis xyz="0 0 1"/>
    <limit effort="200" lower="-3.14159" upper="3.14159" velocity="40"/>
  </joint>
  <gazebo reference="pan_tilt_BASE">
    <mu1>0.9</mu1>
    <mu2>0.9</mu2>
  </gazebo>
  <link name="pan_tilt_PAN_BASE">
    <inertial>
      <mass value="0.1"/>
      <origin rpy="0 0 0" xyz="0.0 -0.012 0.0015"/>
      <inertia ixx="3.202708e-05" ixy="0.0" ixz="0.0" iyy="2.077708e-05" iyz="3.549874e-37" izz="2.478750e-05"/>
    </inertial>
    <visual>
      <origin rpy="0.00000000 -0.00000000 0.00000000" xyz="0.000000 0.000000 0.000000"/>
      <geometry>
        <mesh filename="package://ur_e_description/pan_tilt/meshes/xm430_dynamixel.dae" scale="1.000000 1.000000 1.000000"/>
      </geometry>
    </visual>
    <collision>
      <origin rpy="0.00000000 -0.00000000 0.00000000" xyz="0.000000 0.000000 0.000000"/>
      <geometry>
        <mesh filename="package://ur_e_description/pan_tilt/meshes/xm430_dynamixel.dae" scale="1.000000 1.000000 1.000000"/>
      </geometry>
    </collision>
  </link>
  <gazebo reference="pan_tilt_LINK1">
    <mu1>0.9</mu1>
    <mu2>0.9</mu2>
  </gazebo>
  <link name="pan_tilt_LINK1">
    <inertial>
      <mass value="0.015"/>
      <origin rpy="0 0 0" xyz="-0.01345 9.706125e-18 -0.019"/>
      <inertia ixx="3.012500e-06" ixy="-7.524859e-22" ixz="-9.466331e-38" iyy="1.969763e-06" iyz="8.407791e-53" izz="3.159763e-06"/>
    </inertial>
    <visual>
      <origin rpy="0.00000000 1.57079633 1.57079633" xyz="0.000000 0.000000 -0.019000"/>
      <geometry>
        <mesh filename="package://ur_e_description/pan_tilt/meshes/fr12_h101.dae" scale="1.000000 1.000000 1.000000"/>
      </geometry>
    </visual>
    <collision>
      <origin rpy="0.00000000 1.57079633 1.57079633" xyz="0.000000 0.000000 -0.019000"/>
      <geometry>
        <mesh filename="package://ur_e_description/pan_tilt/meshes/fr12_h101.dae" scale="1.000000 1.000000 1.000000"/>
      </geometry>
    </collision>
  </link>
  <transmission name="pan_tilt_JOINT1_trans">
    <type>transmission_interface/SimpleTransmission</type>
    <joint name="pan_tilt_JOINT1">
      <hardwareInterface>hardware_interface/VelocityJointInterface</hardwareInterface>
      <!--hardwareInterface>hardware_interface/EffortJointInterface</hardwareInterface-->
    </joint>
    <actuator name="pan_tilt_JOINT1_motor">
      <hardwareInterface>hardware_interface/VelocityJointInterface</hardwareInterface>
      <!--hardwareInterface>hardware_interface/EffortJointInterface</hardwareInterface-->
      <mechanicalReduction>1</mechanicalReduction>
    </actuator>
  </transmission>
  <joint name="pan_tilt_JOINT1" type="revolute">
    <parent link="pan_tilt_PAN_BASE"/>
    <child link="pan_tilt_LINK1"/>
    <origin rpy="0.00000000 -0.00000000 0.00000000" xyz="0.000000 0.000000 0.019000"/>
    <axis xyz="0 0 1"/>
    <limit effort="200" lower="-3.14159" upper="3.14159" velocity="40"/>
  </joint>
  <joint name="pan_tilt_tilt_to_pan" type="fixed">
    <parent link="pan_tilt_LINK0"/>
    <child link="pan_tilt_PAN_BASE"/>
    <origin rpy="0.0 1.57079633 0.0" xyz="0.0 0.0 0.016"/>
  </joint>
  <joint name="camera_rgb_joint" type="fixed">
    <origin rpy="-1.57079633 0.0 1.57079633" xyz="-0.08 0.03 -0.045"/>
    <parent link="pan_tilt_LINK1"/>
    <child link="camera_rgb_frame"/>
  </joint>
  <link name="camera_rgb_frame"/>
  <joint name="camera_rgb_optical_joint" type="fixed">
    <origin rpy="-1.57079632679 0 -1.57079632679" xyz="0 0 0"/>
    <parent link="camera_rgb_frame"/>
    <child link="camera_rgb_optical_frame"/>
  </joint>
  <link name="camera_rgb_optical_frame"/>
  <joint name="camera_joint" type="fixed">
    <origin rpy="0 0 0" xyz="-0.031 -0.03 -0.016"/>
    <parent link="camera_rgb_frame"/>
    <child link="camera_link"/>
  </joint>
  <link name="camera_link">
    <visual>
      <origin rpy="0 0 1.57079632679" xyz="0 0 0"/>
      <geometry>
        <mesh filename="package://ur_e_description/pan_tilt/meshes/kinect.dae"/>
      </geometry>
    </visual>
    <collision>
      <origin rpy="0 0 0" xyz="0.0 0.0 0.0"/>
      <geometry>
        <box size="0.07271 0.27794 0.073"/>
      </geometry>
    </collision>
    <inertial>
      <mass value="0.564"/>
      <origin xyz="0 0 0"/>
      <inertia ixx="0.003881243" ixy="0.0" ixz="0.0" iyy="0.000498940" iyz="0.0" izz="0.003879257"/>
    </inertial>
  </link>
  <!-- The fixed joints & links below are usually published by static_transformers launched by the OpenNi launch 
         files. However, for Gazebo simulation we need them, so we add them here.
         (Hence, don't publish them additionally!) -->
  <joint name="camera_depth_joint" type="fixed">
    <origin rpy="0 0 0" xyz="0 -0.06 0"/>
    <parent link="camera_rgb_frame"/>
    <child link="camera_depth_frame"/>
  </joint>
  <link name="camera_depth_frame"/>
  <joint name="camera_depth_optical_joint" type="fixed">
    <origin rpy="-1.57079632679 0 -1.57079632679" xyz="0 0 0"/>
    <parent link="camera_depth_frame"/>
    <child link="camera_depth_optical_frame"/>
  </joint>
  <link name="camera_depth_optical_frame"/>
  <gazebo reference="camera_link">
    <sensor name="camera" type="depth">
      <always_on>true</always_on>
      <update_rate>20.0</update_rate>
      <camera>
        <horizontal_fov>1.0471975512</horizontal_fov>
        <image>
          <format>B8G8R8</format>
          <width>640</width>
          <height>480</height>
        </image>
        <clip>
          <near>0.05</near>
          <far>8.0</far>
        </clip>
      </camera>
      <plugin filename="libgazebo_ros_openni_kinect.so" name="kinect_camera_controller">
        <cameraName>camera</cameraName>
        <alwaysOn>true</alwaysOn>
        <updateRate>10</updateRate>
        <imageTopicName>rgb/image_raw</imageTopicName>
        <depthImageTopicName>depth/image_raw</depthImageTopicName>
        <pointCloudTopicName>depth/points</pointCloudTopicName>
        <cameraInfoTopicName>rgb/camera_info</cameraInfoTopicName>
        <depthImageCameraInfoTopicName>depth/camera_info</depthImageCameraInfoTopicName>
        <frameName>camera_depth_optical_frame</frameName>
        <baseline>0.1</baseline>
        <distortion_k1>0.0</distortion_k1>
        <distortion_k2>0.0</distortion_k2>
        <distortion_k3>0.0</distortion_k3>
        <distortion_t1>0.0</distortion_t1>
        <distortion_t2>0.0</distortion_t2>
        <pointCloudCutoff>0.4</pointCloudCutoff>
      </plugin>
    </sensor>
  </gazebo>
  <joint name="base_to_head" type="fixed">
    <parent link="dual_arm_base"/>
    <child link="pan_tilt_BASE"/>
    <origin rpy="0.0 0.0 -1.5707963267949" xyz="0.08 0.0 1.505"/>
  </joint>
  <transmission name="right_joint1_trans">
    <type>transmission_interface/SimpleTransmission</type>
    <joint name="right_joint1">
      <hardwareInterface>hardware_interface/VelocityJointInterface</hardwareInterface>
    </joint>
    <actuator name="right_joint1_motor">
      <hardwareInterface>hardware_interface/VelocityJointInterface</hardwareInterface>
      <mechanicalReduction>1</mechanicalReduction>
    </actuator>
  </transmission>
  <transmission name="right_joint2_trans">
    <type>transmission_interface/SimpleTransmission</type>
    <joint name="right_joint2">
      <hardwareInterface>hardware_interface/VelocityJointInterface</hardwareInterface>
    </joint>
    <actuator name="right_joint2_motor">
      <hardwareInterface>hardware_interface/VelocityJointInterface</hardwareInterface>
      <mechanicalReduction>1</mechanicalReduction>
    </actuator>
  </transmission>
  <transmission name="right_joint3_trans">
    <type>transmission_interface/SimpleTransmission</type>
    <joint name="right_joint3">
      <hardwareInterface>hardware_interface/VelocityJointInterface</hardwareInterface>
    </joint>
    <actuator name="right_joint3_motor">
      <hardwareInterface>hardware_interface/VelocityJointInterface</hardwareInterface>
      <mechanicalReduction>1</mechanicalReduction>
    </actuator>
  </transmission>
  <transmission name="right_joint4_trans">
    <type>transmission_interface/SimpleTransmission</type>
    <joint name="right_joint4">
      <hardwareInterface>hardware_interface/VelocityJointInterface</hardwareInterface>
    </joint>
    <actuator name="right_joint4_motor">
      <hardwareInterface>hardware_interface/VelocityJointInterface</hardwareInterface>
      <mechanicalReduction>1</mechanicalReduction>
    </actuator>
  </transmission>
  <transmission name="right_joint5_trans">
    <type>transmission_interface/SimpleTransmission</type>
    <joint name="right_joint5">
      <hardwareInterface>hardware_interface/VelocityJointInterface</hardwareInterface>
    </joint>
    <actuator name="right_joint5_motor">
      <hardwareInterface>hardware_interface/VelocityJointInterface</hardwareInterface>
      <mechanicalReduction>1</mechanicalReduction>
    </actuator>
  </transmission>
  <transmission name="right_joint6_trans">
    <type>transmission_interface/SimpleTransmission</type>
    <joint name="right_joint6">
      <hardwareInterface>hardware_interface/VelocityJointInterface</hardwareInterface>
    </joint>
    <actuator name="right_joint6_motor">
      <hardwareInterface>hardware_interface/VelocityJointInterface</hardwareInterface>
      <mechanicalReduction>1</mechanicalReduction>
    </actuator>
  </transmission>
  <transmission name="right_joint7_trans">
    <type>transmission_interface/SimpleTransmission</type>
    <joint name="right_joint7">
      <hardwareInterface>hardware_interface/VelocityJointInterface</hardwareInterface>
    </joint>
    <actuator name="right_joint7_motor">
      <hardwareInterface>hardware_interface/VelocityJointInterface</hardwareInterface>
      <mechanicalReduction>1</mechanicalReduction>
    </actuator>
  </transmission>
  <transmission name="left_joint1_trans">
    <type>transmission_interface/SimpleTransmission</type>
    <joint name="left_joint1">
      <hardwareInterface>hardware_interface/VelocityJointInterface</hardwareInterface>
    </joint>
    <actuator name="left_joint1_motor">
      <hardwareInterface>hardware_interface/VelocityJointInterface</hardwareInterface>
      <mechanicalReduction>1</mechanicalReduction>
    </actuator>
  </transmission>
  <transmission name="left_joint2_trans">
    <type>transmission_interface/SimpleTransmission</type>
    <joint name="left_joint2">
      <hardwareInterface>hardware_interface/VelocityJointInterface</hardwareInterface>
    </joint>
    <actuator name="left_joint2_motor">
      <hardwareInterface>hardware_interface/VelocityJointInterface</hardwareInterface>
      <mechanicalReduction>1</mechanicalReduction>
    </actuator>
  </transmission>
  <transmission name="left_joint3_trans">
    <type>transmission_interface/SimpleTransmission</type>
    <joint name="left_joint3">
      <hardwareInterface>hardware_interface/VelocityJointInterface</hardwareInterface>
    </joint>
    <actuator name="left_joint3_motor">
      <hardwareInterface>hardware_interface/VelocityJointInterface</hardwareInterface>
      <mechanicalReduction>1</mechanicalReduction>
    </actuator>
  </transmission>
  <transmission name="left_joint4_trans">
    <type>transmission_interface/SimpleTransmission</type>
    <joint name="left_joint4">
      <hardwareInterface>hardware_interface/VelocityJointInterface</hardwareInterface>
    </joint>
    <actuator name="left_joint4_motor">
      <hardwareInterface>hardware_interface/VelocityJointInterface</hardwareInterface>
      <mechanicalReduction>1</mechanicalReduction>
    </actuator>
  </transmission>
  <transmission name="left_joint5_trans">
    <type>transmission_interface/SimpleTransmission</type>
    <joint name="left_joint5">
      <hardwareInterface>hardware_interface/VelocityJointInterface</hardwareInterface>
    </joint>
    <actuator name="left_joint5_motor">
      <hardwareInterface>hardware_interface/VelocityJointInterface</hardwareInterface>
      <mechanicalReduction>1</mechanicalReduction>
    </actuator>
  </transmission>
  <transmission name="left_joint6_trans">
    <type>transmission_interface/SimpleTransmission</type>
    <joint name="left_joint6">
      <hardwareInterface>hardware_interface/VelocityJointInterface</hardwareInterface>
    </joint>
    <actuator name="left_joint6_motor">
      <hardwareInterface>hardware_interface/VelocityJointInterface</hardwareInterface>
      <mechanicalReduction>1</mechanicalReduction>
    </actuator>
  </transmission>
  <transmission name="left_joint7_trans">
    <type>transmission_interface/SimpleTransmission</type>
    <joint name="left_joint7">
      <hardwareInterface>hardware_interface/VelocityJointInterface</hardwareInterface>
    </joint>
    <actuator name="left_joint7_motor">
      <hardwareInterface>hardware_interface/VelocityJointInterface</hardwareInterface>
      <mechanicalReduction>1</mechanicalReduction>
    </actuator>
  </transmission>
  <transmission name="right_finger_joint1_trans">
    <type>transmission_interface/SimpleTransmission</type>
    <joint name="right_finger_joint1">
      <hardwareInterface>hardware_interface/VelocityJointInterface</hardwareInterface>
    </joint>
    <actuator name="right_finger_joint1_motor">
      <hardwareInterface>hardware_interface/VelocityJointInterface</hardwareInterface>
      <mechanicalReduction>1</mechanicalReduction>
    </actuator>
  </transmission>
  <transmission name="right_finger_joint2_trans">
    <type>transmission_interface/SimpleTransmission</type>
    <joint name="right_finger_joint2">
      <hardwareInterface>hardware_interface/VelocityJointInterface</hardwareInterface>
    </joint>
    <actuator name="right_finger_joint2_motor">
      <hardwareInterface>hardware_interface/VelocityJointInterface</hardwareInterface>
      <mechanicalReduction>1</mechanicalReduction>
    </actuator>
  </transmission>
  <transmission name="left_finger_joint1_trans">
    <type>transmission_interface/SimpleTransmission</type>
    <joint name="left_finger_joint1">
      <hardwareInterface>hardware_interface/VelocityJointInterface</hardwareInterface>
    </joint>
    <actuator name="left_finger_joint1_motor">
      <hardwareInterface>hardware_interface/VelocityJointInterface</hardwareInterface>
      <mechanicalReduction>1</mechanicalReduction>
    </actuator>
  </transmission>
  <transmission name="left_finger_joint2_trans">
    <type>transmission_interface/SimpleTransmission</type>
    <joint name="left_finger_joint2">
      <hardwareInterface>hardware_interface/VelocityJointInterface</hardwareInterface>
    </joint>
    <actuator name="left_finger_joint2_motor">
      <hardwareInterface>hardware_interface/VelocityJointInterface</hardwareInterface>
      <mechanicalReduction>1</mechanicalReduction>
    </actuator>
  </transmission>
  <!-- create camera frame-->
  <link name="fisheye_frame"/>
  <joint name="fisheye_fixed_joint" type="fixed">
    <parent link="dual_arm_base"/>
    <child link="fisheye_frame"/>
    <origin rpy="0 1.3 0" xyz="0.07 0 1.9"/>
  </joint>
  <!-- camera -->
  <gazebo reference="fisheye_frame">
    <sensor name="fisheye_camera_sensor" type="wideanglecamera">
      <!--pose>${pose}</pose-->
      <always_on>true</always_on>
      <update_rate>15</update_rate>
      <visualize>false</visualize>
      <camera name="fisheye_camera">
        <horizontal_fov>3.14</horizontal_fov>
        <image>
          <width>2048</width>
          <height>2048</height>
          <format>R8G8B8</format>
        </image>
        <clip>
          <near>0.02</near>
          <far>300</far>
        </clip>
        <lens>
          <!-- for Fisheye -->
          <!-- type: gnomonical, stereographic, equidistant, equisolid_angle, orthographic, custom -->
          <!-- More information here: https://en.wikipedia.org/wiki/Fisheye_lens#Mapping_function -->
          <!--type>equidistant</type-->
          <type>custom</type>
          <!-- manually defined mapping function r = c1*f*fun(theta/c2 + c3) -->
          <custom_function>
            <c1>2</c1>
            <c2>2</c2>
            <c3>0</c3>
            <f>0.63661977</f>
            <!-- ( 2.0 / pi ) -->
            <fun>id</fun>
            <!-- one of sin,tan,id -->
          </custom_function>
          <!-- if it is set to `true` your horizontal FOV will ramain as defined -->
          <!-- othervise it depends on lens type and custom function, if there is one -->
          <scale_to_hfov>false</scale_to_hfov>
          <cutoff_angle>1.5707</cutoff_angle>
          <!-- clip everything that is outside of this angle -->
          <!-- resolution of the cubemap texture, the highter it is - the sharper is your image -->
          <env_texture_size>2048</env_texture_size>
        </lens>
      </camera>
      <plugin filename="libgazebo_ros_camera.so" name="camera_controller">
        <alwaysOn>true</alwaysOn>
        <updateRate>0.0</updateRate>
        <!-- ? -->
        <cameraName>fisheye_camera</cameraName>
        <imageTopicName>image_raw</imageTopicName>
        <cameraInfoTopicName>camera_info</cameraInfoTopicName>
        <frameName>fisheye_frame</frameName>
        <hackBaseline>0.07</hackBaseline>
        <distortionK1>0.0</distortionK1>
        <distortionK2>0.0</distortionK2>
        <distortionK3>0.0</distortionK3>
        <distortionT1>0.0</distortionT1>
        <distortionT2>0.0</distortionT2>
      </plugin>
    </sensor>
  </gazebo>
  <gazebo>
    <plugin filename="libgazebo_ros_control.so" name="gazebo_ros_control">
      <!--robotNamespace>/</robotNamespace-->
      <legacyModeNS>false</legacyModeNS>
      <robotSimType>gazebo_ros_control/DefaultRobotHWSim</robotSimType>
    </plugin>
  </gazebo>
</robot>

